<?xml version="1.0"?>
<!-- Basic differential drive mobile base -->
<robot xmlns:xacro="http://www.ros.org/wiki/xacro" name="diffdrive_robot">
  <xacro:arg name="prefix" default="" />
  <xacro:arg name="use_mock_hardware" default="false" />

  <!-- ROS2 Control macro definition -->
  <xacro:macro name="diffbot_ros2_control" params="name prefix use_mock_hardware">
    <ros2_control name="${name}" type="system">
      <xacro:unless value="${use_mock_hardware}">
        <hardware>
          <plugin>rasptank_diff_drive/DiffBotSystemHardware</plugin>
          <param name="example_param_hw_start_duration_sec">0</param>
          <param name="example_param_hw_stop_duration_sec">3.0</param>
        </hardware>
      </xacro:unless>
      <xacro:if value="${use_mock_hardware}">
        <hardware>
          <plugin>mock_components/GenericSystem</plugin>
          <param name="calculate_dynamics">true</param>
        </hardware>
      </xacro:if>
      <joint name="${prefix}left_wheel_joint">
        <command_interface name="velocity"/>
        <state_interface name="position"/>
        <state_interface name="velocity"/>
      </joint>
      <joint name="${prefix}right_wheel_joint">
        <command_interface name="velocity"/>
        <state_interface name="position"/>
        <state_interface name="velocity"/>
      </joint>
    </ros2_control>
  </xacro:macro>

  <!-- Robot base link -->
  <link name="${prefix}base_link">
    <visual>
      <origin xyz="0 0 0.05" rpy="0 0 0"/>
      <geometry>
        <box size="0.3 0.2 0.1"/>
      </geometry>
      <material name="blue">
        <color rgba="0 0 1 1"/>
      </material>
    </visual>
    <collision>
      <origin xyz="0 0 0.05" rpy="0 0 0"/>
      <geometry>
        <box size="0.3 0.2 0.1"/>
      </geometry>
    </collision>
    <inertial>
      <origin xyz="0 0 0.05" rpy="0 0 0"/>
      <mass value="1.0"/>
      <inertia ixx="0.1" ixy="0" ixz="0" iyy="0.1" iyz="0" izz="0.1"/>
    </inertial>
  </link>

  <!-- Left wheel -->
  <link name="${prefix}left_wheel">
    <visual>
      <origin xyz="0 0 0" rpy="1.5708 0 0"/>
      <geometry>
        <cylinder radius="0.05" length="0.04"/>
      </geometry>
      <material name="black">
        <color rgba="0 0 0 1"/>
      </material>
    </visual>
    <collision>
      <origin xyz="0 0 0" rpy="1.5708 0 0"/>
      <geometry>
        <cylinder radius="0.05" length="0.04"/>
      </geometry>
    </collision>
    <inertial>
      <origin xyz="0 0 0" rpy="1.5708 0 0"/>
      <mass value="0.1"/>
      <inertia ixx="0.001" ixy="0" ixz="0" iyy="0.001" iyz="0" izz="0.001"/>
    </inertial>
  </link>

  <!-- Right wheel -->
  <link name="${prefix}right_wheel">
    <visual>
      <origin xyz="0 0 0" rpy="1.5708 0 0"/>
      <geometry>
        <cylinder radius="0.05" length="0.04"/>
      </geometry>
      <material name="black">
        <color rgba="0 0 0 1"/>
      </material>
    </visual>
    <collision>
      <origin xyz="0 0 0" rpy="1.5708 0 0"/>
      <geometry>
        <cylinder radius="0.05" length="0.04"/>
      </geometry>
    </collision>
    <inertial>
      <origin xyz="0 0 0" rpy="1.5708 0 0"/>
      <mass value="0.1"/>
      <inertia ixx="0.001" ixy="0" ixz="0" iyy="0.001" iyz="0" izz="0.001"/>
    </inertial>
  </link>

  <!-- Left wheel joint -->
  <joint name="${prefix}left_wheel_joint" type="continuous">
    <origin xyz="0 0.11 0" rpy="0 0 0"/>
    <parent link="${prefix}base_link"/>
    <child link="${prefix}left_wheel"/>
    <axis xyz="0 1 0"/>
  </joint>

  <!-- Right wheel joint -->
  <joint name="${prefix}right_wheel_joint" type="continuous">
    <origin xyz="0 -0.11 0" rpy="0 0 0"/>
    <parent link="${prefix}base_link"/>
    <child link="${prefix}right_wheel"/>
    <axis xyz="0 1 0"/>
  </joint>

  <!-- ROS2 Control -->
  <xacro:diffbot_ros2_control
    name="DiffBot" prefix="$(arg prefix)" use_mock_hardware="$(arg use_mock_hardware)"/>

</robot>
